<?xml version="1.0" ?>
<robot name="point_foot" xmlns:xacro="http://www.ros.org/wiki/xacro">
  <material name="black">
    <color rgba="0.0 0.0 0.0 1.0"/>
  </material>
  <material name="blue">
    <color rgba="0.0 0.0 0.8 1.0"/>
  </material>
  <material name="green">
    <color rgba="0.0 0.8 0.0 1.0"/>
  </material>
  <material name="grey">
    <color rgba="0.2 0.2 0.2 1.0"/>
  </material>
  <material name="silver">
    <color rgba="0.913725490196 0.913725490196 0.847058823529 1.0"/>
  </material>
  <material name="orange">
    <color rgba="0.12 0.15 0.2 1.0"/>
  </material>
  <material name="brown">
    <color rgba="0.870588235294 0.811764705882 0.764705882353 1.0"/>
  </material>
  <material name="red">
    <color rgba="0.8 0.0 0.0 1.0"/>
  </material>
  <material name="white">
    <color rgba="1.0 1.0 1.0 1.0"/>
  </material>
<link name="base_Link">
    <visual>
      <origin rpy="0 0 0" xyz="0 0 0.14"/>
      <geometry>
         <box size="0.12 0.18 0.15"/>
      </geometry>
      <material name="white"/>
    </visual>
    <!--<geometry>
       <mesh filename="../meshes/base_link.STL"/>
     </geometry> -->
    <collision>
      <origin rpy="0 0 0" xyz="0.03 0 0.14"/>
      <geometry>
        <box size="0.13 0.16 0.12"/>
      </geometry>
    </collision>
    <inertial>
      <!-- <origin rpy="0 0 0" xyz="0.03265 0.00208  0.06345"/> -->
      <origin rpy="0 0 0" xyz="0.03265 0.00208  0.06345"/>
      <mass value="5.6"/> 
      <!-- <inertia ixx="0.04275" ixy="0" ixz="0" iyy=" 0.063975" iyz="0" izz="0.03365"/> -->
      <!-- <inertia ixx="0.06388" ixy="0.00028" ixz="0.00564" iyy=" 0.06802" iyz="0.00101" izz="0.03926"/> -->
      <inertia ixx="0.04388" ixy="0.00028" ixz="0.00564" iyy=" 0.05802" iyz="0.00101" izz="0.04926"/>
      <!-- <inertia ixx="0.06582" ixy="−0.000363" ixz="0" iyy=" 0.06255" iyz="0.000989" izz="0.02758"/> -->
     
        </inertial>
  </link>
<!--
  <joint name="imu_joint" type="fixed">
        <origin rpy="0. 0. 0." xyz="0. 0. 0."/>
        <parent link="base_Link"/>
        <child link="imu"/>
    </joint>
  
      <link name="imu">
        <inertial>
            <mass value="0.01"/>
            <origin rpy="0 0 0" xyz="0 0 0"/>
            <inertia ixx="0.000001" ixy="0" ixz="0" iyy="0.000001" iyz="0" izz="0.000001"/>
        </inertial>
        <visual>
            <origin rpy="0 0 0" xyz="0 0 0"/>
            <geometry>
                <box size="0.015 0.015 0.004"/>
            </geometry>
        </visual>
        <material name="orange">
            <color rgba="255 108 10 255"/>
        </material>
    </link>  -->

  <!--*****************************L****************************************-->
      <link
            name="L_Abad_Link">
          <inertial>
      <origin
        xyz="0 0.0033685 0"
        rpy="0 0 0" />
      <mass
        value="0.84142" />
      <inertia
        ixx="0.00044078"
        ixy="-9.9392E-08"
        ixz="-3.6784E-07"
        iyy="0.00074812"
        iyz="-4.4651E-08"
        izz="0.00040238" />
    </inertial>
        <visual>   
            <origin
                    xyz="0 0 0"
                    rpy="1.57  0 0"/>
	     <geometry>
		  <cylinder length="0.035" radius="0.04"/>
	      </geometry>
            <material name="white"/>
        </visual>
        <collision>
            <origin rpy=" 1.57 0 0" xyz="0 0.0 0"/>
            <geometry>
                 <cylinder length="0.035" radius="0.04"/>
            </geometry>
        </collision> 
      </link>
    <joint
            name="L_abad_joint"
            type="revolute">
        <origin
                xyz="0 0.06 0"
                rpy="0 0 0"/>
        <parent
                link="base_Link"/>
        <child
                link="L_Abad_Link"/>
        <axis
                xyz="1 0 0"/>
        <limit effort="40.0" lower="-0.4" upper="0.4" velocity="30.0"/>
    </joint>

  <!--*****************************hip**************************************-->
  
  <link name="L_hip_Link">
    <visual>
           <origin rpy="0 0 0" xyz="0 0 0"/>
      <geometry>
        <mesh
          filename="../meshes/L_hip_Link.STL" />
      </geometry>
      <material name="silver"/>
    </visual>
    <collision>
      <origin rpy="0 0 0" xyz="0 0 -0.1"/>
      <geometry>
           <cylinder length="0.15" radius="0.02"/>
      </geometry>
    </collision>
    <inertial>
      <origin
        xyz="-0.0029051 -0.021376 -0.028346"
        rpy="0 0 0" />
      <mass
        value="1.0967" />
      <inertia
        ixx="0.0021496"
        ixy="1.1839E-06"
        ixz="-4.8995E-05"
        iyy="0.0026093"
        iyz="1.3229E-05"
        izz="0.00052605" />
    </inertial>
  </link>

  <joint name="L_hip_joint" type="revolute">
    <origin rpy="0 0 0" xyz="0 0.0875  0"/>
    <parent link="L_Abad_Link"/>
    <child link="L_hip_Link"/>
    <axis xyz="0 -1 0"/>
    <dynamics damping="0" friction="0"/>
    <limit effort="40.0" lower="-1.3" upper="1.3" velocity="30.0"/>
  </joint>

<link name="L_knee_Link">
    <visual>
      <origin rpy="0 0 0" xyz="0 0 0"/>
      <geometry>
        <mesh filename="../meshes/L_knee_Link.STL" scale="1 1 1"/>
      </geometry>
      <material name="silver"/>
    </visual>

    <collision>
      <origin rpy="0 -0.21 0" xyz="0.008 0 -0.06"/>
      <geometry>
      	<cylinder length="0.12" radius="0.012" />
        <!--<box size="0.2 0.016 0.016"/>-->
      </geometry>
    </collision>
    <inertial>
      <origin rpy="0 0 0" xyz="0.006435 0.0 -0.107388"/>
       <mass
        value="0.154" />
      <inertia
        ixx="0.00108"
        ixy="3.4E-07"
        ixz="1.72E-05"
        iyy="0.0011"
        iyz="8.28E-06"
        izz="3.29E-05" />
    </inertial>
  </link>
 <joint name="L_knee_joint" type="revolute">
    <origin rpy="0 0 0" xyz="0 0 -0.22"/>
    <parent link="L_hip_Link"/>
    <child link="L_knee_Link"/>
    <axis xyz="0 -1 0"/>
    <dynamics damping="0" friction="0"/>
    <limit effort="40" lower="0.5" upper="2.3" velocity="30"/>
  </joint>

<link
    name="L_kneeflower">
    <collision>
      <origin rpy="0 0 0" xyz="0 0 0" />
      <geometry>
        <cylinder length="0.07" radius="0.011" />
      </geometry>
    </collision>
  </link>
  <joint
    name="L_kneeflower_joint"
    type="fixed">
    <origin
      xyz="0.020 0 -0.152"
      rpy="0 0.05 0" />
    <parent
      link="L_knee_Link" />
    <child
      link="L_kneeflower" />
    <axis
      xyz="0 0 0" />
  </joint>
  <link
    name="L_kneeflower1">
    <collision>
      <origin rpy="0 0 0" xyz="0 0 0" />
      <geometry>
        <cylinder length="0.038" radius="0.012" />
      </geometry>
    </collision>
  </link>
  <joint
    name="L_kneeflower1_joint"
    type="fixed">
    <origin
      xyz="-0.006 0 -0.05"
      rpy="0 0.3 0" />
    <parent
      link="L_kneeflower" />
    <child
      link="L_kneeflower1" />
    <axis
      xyz="0 0 0" />
  </joint>
  <link
    name="L_foot">
    <inertial>
      <origin
        xyz="-0.039445 -3.2459E-08 -0.17051"
        rpy="0 0 0" />
      <mass
        value="0.010414" />
      <inertia
        ixx="2.0696E-05"
        ixy="-4.0041E-12"
        ixz="4.8649E-07"
        iyy="1.6231E-06"
        iyz="1.0208E-11"
        izz="2.1532E-05" />
    </inertial>
    <visual>
      <origin
        xyz="0 0 0"
        rpy="0 0 0" />
      <geometry>
        <sphere radius="0.022" />
      </geometry>
      <material
        name="">
        <color
          rgba="1 1 1 1" />
      </material>
    </visual>
    <collision>
      <origin rpy="0 0 0" xyz="0 0 0" />
      <geometry>
        <sphere radius="0.022" />
      </geometry>
    </collision>
  </link>
  <joint
    name="L_foot_joint"
    type="fixed" dont_collapse="true">
    <origin
      xyz="0.0 0 -0.232"
      rpy="0 0 0" />
    <parent
      link="L_knee_Link" />
    <child
      link="L_foot" />
    <axis
      xyz="0 0 0" />
  </joint>


  <!--*****************************right leg**************************************-->
 
     <link
            name="R_Abad_Link">
       <inertial>
      <origin
        xyz="0 -0.0033685 0"
        rpy="0 0 0" />
      <mass
        value="0.84142" />
      <inertia
        ixx="0.00044085"
        ixy="6.4555E-07"
        ixz="-2.9232E-07"
        iyy="0.00074812"
        iyz="9.7511E-08"
        izz="0.0004023" />
    </inertial>
        <visual>   
            <origin
                    xyz="0 0 0"
                    rpy="1.57  0 0"/>
	     <geometry>
	 	    <cylinder length="0.035" radius="0.04"/>
	      </geometry>
            <material name="white"/>
        </visual>
        <collision>
            <origin rpy=" 1.57 0 0" xyz="0 0.0 0"/>
            <geometry>
                 <cylinder length="0.035" radius="0.04"/>
            </geometry>
        </collision> 
      </link>
    <joint
            name="R_abad_joint"
            type="revolute">
        <origin
                xyz="0 -0.06 0"
                rpy="0 0 0"/>
        <parent
                link="base_Link"/>
        <child
                link="R_Abad_Link"/>
        <axis
                xyz="1 0 0"/>
        <limit effort="40.0" lower="-0.4" upper="0.4" velocity="30.0"/>
    </joint>

  <!--*****************************hip**************************************-->

  <link name="R_hip_Link">
    <visual>
           <origin rpy="0 0 0" xyz="0 0 0"/>
      <geometry>
         <mesh
          filename="../meshes/R_hip_Link.STL" />
      </geometry>
      <material name="silver"/>
    </visual>
   <collision>
      <origin rpy="0 0 0" xyz="0 0 -0.1"/>
      <geometry>
         <cylinder length="0.15" radius="0.02"/>
 <!--<box size="0.15 0.03 0.04"/>-->
      </geometry>
    </collision> 
    <inertial>
      <origin
        xyz="-0.0029051 0.021376 -0.028346"
        rpy="0 0 0" />
       <mass
        value="1.0967" />
      <inertia
        ixx="0.0021496"
        ixy="1.1839E-06"
        ixz="-4.8995E-05"
        iyy="0.0026093"
        iyz="1.3229E-05"
        izz="0.00052605" />
    </inertial>
  </link>

  <joint name="R_hip_joint" type="revolute">
    <origin rpy="0 0 0" xyz="0 -0.0875  0"/>
    <parent link="R_Abad_Link"/>
    <child link="R_hip_Link"/>
    <axis xyz="0 -1 0"/>
    <dynamics damping="0" friction="0"/>
    <limit effort="40" lower="-1.3" upper="1.3" velocity="30"/>
  </joint>


  <!--*****************************RF***thigh*************************************-->
<link name="R_knee_Link">
    <visual>
      <origin rpy="0 0 0" xyz="0 0 0"/>
      <geometry>
        <mesh filename="../meshes/R_knee_Link.STL" scale="1 1 1"/>
      </geometry>
      <material name="silver"/>
    </visual>

    <collision>
      <origin rpy="0 -0.21 0" xyz="0.008 0 -0.06"/>
      <geometry>
      	<cylinder length="0.12" radius="0.012" />
        <!--<box size="0.2 0.016 0.016"/>-->
      </geometry>
    </collision>
    <inertial>
      <origin rpy="0 0 0" xyz="0.006435 0.0 -0.107388"/>
       <mass
        value="0.154" />
      <inertia
        ixx="0.00108"
        ixy="3.4E-07"
        ixz="1.72E-05"
        iyy="0.0011"
        iyz="8.28E-06"
        izz="3.29E-05" />
    </inertial>
  </link>
 <joint name="R_knee_joint" type="revolute">
    <origin rpy="0 0 0" xyz="0 0 -0.22"/>
    <parent link="R_hip_Link"/>
    <child link="R_knee_Link"/>
    <axis xyz="0 -1 0"/>
    <dynamics damping="0" friction="0"/>
    <limit effort="40" lower="0.5" upper="2.3" velocity="30"/>
  </joint>

<link
    name="R_kneeflower">
    <collision>
      <origin rpy="0 0 0" xyz="0 0 0" />
      <geometry>
        <cylinder length="0.07" radius="0.011" />
      </geometry>
    </collision>
  </link>
  <joint
    name="R_kneeflower_joint"
    type="fixed">
    <origin
      xyz="0.020 0 -0.152"
      rpy="0 0.05 0" />
    <parent
      link="R_knee_Link" />
    <child
      link="R_kneeflower" />
    <axis
      xyz="0 0 0" />
  </joint>
  <link
    name="R_kneeflower1">
    <collision>
      <origin rpy="0 0 0" xyz="0 0 0" />
      <geometry>
        <cylinder length="0.038" radius="0.012" />
      </geometry>
    </collision>
  </link>
  <joint
    name="R_kneeflower1_joint"
    type="fixed">
    <origin
      xyz="-0.006 0 -0.05"
      rpy="0 0.3 0" />
    <parent
      link="R_kneeflower" />
    <child
      link="R_kneeflower1" />
    <axis
      xyz="0 0 0" />
  </joint>
  <link
    name="R_foot">
     <inertial>
      <origin
        xyz="-0.039445 -8.832E-09 -0.17051"
        rpy="0 0 0" />
      <mass
        value="0.010414" />
      <inertia
        ixx="2.0696E-05"
        ixy="-4.0041E-12"
        ixz="4.8649E-07"
        iyy="1.6231E-06"
        iyz="1.0208E-11"
        izz="2.1532E-05" />
    </inertial>
    <visual>
      <origin
        xyz="0 0 0"
        rpy="0 0 0" />
      <geometry>
        <sphere radius="0.022" />
      </geometry>
      <material
        name="">
        <color
          rgba="1 1 1 1" />
      </material>
    </visual>
    <collision>
      <origin rpy="0 0 0" xyz="0 0 0" />
      <geometry>
        <sphere radius="0.022" />
      </geometry>
    </collision>
  </link>
  <joint
    name="R_foot_joint"
    type="fixed" dont_collapse="true">
    <origin
      xyz="0.0 0 -0.232"
      rpy="0 0 0" />
    <parent
      link="R_knee_Link" />
    <child
      link="R_foot" />
    <axis
      xyz="0 0 0" />
  </joint>
</robot>
